Workbook
Name Beg_Bal: '[1]Loan Amortization'!$C$19:$C$378
Name CompanyName: #REF!
Name CustomerLookup: #REF!
Name End_Bal: '[1]Loan Amortization'!$I$19:$I$378
Name Extra_Pay: '[1]Loan Amortization'!$E$19:$E$378
Name Int: '[1]Loan Amortization'!$H$19:$H$378
Name Interest_Rate: '[1]Loan Amortization'!$D$6
Name Invoice_No: #REF!
Name InvoiceNoDetails: "InvoiceDetails[Invoice No]"
Name Loan_Amount: '[1]Loan Amortization'!$D$5
Name Loan_Start: '[1]Loan Amortization'!$D$8
Name Loan_Years: '[1]Loan Amortization'!$D$7
Name Number_of_Payments: MATCH(0.01,End_Bal,-1)+1
Name Number_of_Payments: MATCH(0.01,End_Bal,-1)+1
Name Number_of_Payments: MATCH(0.01,End_Bal,-1)+1
Name Pay_Num: '[1]Loan Amortization'!$A$19:$A$378
Name Princ: '[1]Loan Amortization'!$G$19:$G$378
Name rngInvoice: #REF!
Name Sched_Pay: '[1]Loan Amortization'!$D$19:$D$378
Name Scheduled_Extra_Payments: '[1]Loan Amortization'!$D$9
Name Scheduled_Monthly_Payment: '[1]Loan Amortization'!$D$12
Name Total_Pay: '[1]Loan Amortization'!$F$19:$F$378
Name Values_Entered: IF(Loan_Amount*Interest_Rate*Loan_Years*Loan_Start>0,1,0)
Name Values_Entered: IF(Loan_Amount*Interest_Rate*Loan_Years*Loan_Start>0,1,0)
Name Values_Entered: IF(Loan_Amount*Interest_Rate*Loan_Years*Loan_Start>0,1,0)

Sheet KPIs
A4: Gross Rental Income: $ | B4: ='IS (Combined)'!D16 -> 830313.64
A5: Gross Other Income: $ | B5: ='IS (Combined)'!D31+'IS (Combined)'!D32+'IS (Combined)'!D33+'IS (Combined)'!D34+'IS (Combined)'!D35 -> 87785.74
A6: Operating Expenses: $ (includes property taxes, insurance, maintenance) | B6: ='IS (Combined)'!D81 -> 366889.71
A7: Net Operating Income (NOI): $ | B7: =B4+B5-B6 -> 551209.67
A8: Operating Cash Flow (After Debt Service): $ | B8: ='IS (Combined)'!D85 -> 263727.85
A9: Capital Expenditures: $ (unit renovations and common area upgrades) | B9: ='Fixed Assets'!E15+'Fixed Assets'!E16+'Fixed Assets'!E17+'Fixed Assets'!E18+'Fixed Assets'!E19+55382.62+10221.09+'Fixed Assets'!E20 -> 368524.38
A10: Debt Service Coverage Ratio: | B10: ='IS (Combined)'!D83/-'IS (Combined)'!D84 -> 1.9173723
A13: Property Financial Results | B13: Since Inception
A14: Total Revenues: $ | B14: ='IS (Combined)'!D36 -> 918099.38
A15: Net Operating Income (NOI): $ | B15: ='IS (Combined)'!D83 -> 551209.67
A16: Debt Service & Other: $ | B16: =-'IS (Combined)'!D84 -> 287481.82
A17: Capital Improvements: $ | B17: =B9 -> 368524.38
A18: Operating Cash Flow (After Debt Service): $ | B18: =B8 -> 263727.85
A19: Avg. Occupancy
A21: Inception: April 8, 2025

Sheet Analyzer
B2: #VALUE! | I2: Underwriting Assumptions | N2: Underwriting Comments:
I3: Vacancy Loss % | L3: 0.05
I4: Bad Debt % | L4: 0.02
I5: Concessions % | L5: 0
I7: Rent Escalator | L7: 0.03
I8: Other Income Escalator | L8: 0.01
I9: Expense Escalator | L9: 0.03
C10: Actual Q2 | E10: Budget
B12: ='[2]Data Entry'!B1 -> Allaire on 41st | C12: Since Inception DATA | I12: ACQUISITION (YEAR 0) | L12: POST ACQUISITION
B13: Financial Projections | C13: Actual Q3 | E13: Budget | I13: Acquisition | J13: 45755 | K13: 45838
C14: T3 | E14: T3 | I14: Analysis
B15: Cash Flow Projection: | D15: % | E15: quarters 2 | F15: % | G15: variance | I15: Year 0 | J15: Per Unit | K15: % | L15: Year 1 | M15: Per Unit | N15: % | O15: Year 2 | P15: Per Unit | Q15: % | R15: Year 3 | S15: Per Unit | T15: % | U15: Year 4 | V15: Per Unit | W15: % | X15: Year 5 | Y15: Per Unit | Z15: % | AA15: Year 6 | AB15: % | AC15: Year 7 | AD15: % | AE15: Year 8 | AF15: % | AG15: Year 9 | AH15: % | AI15: Year 10 | AJ15: % | AK15: Comments
B16: Average Rent | I16: =I21/'[2]Data Entry'!$C$11/12 -> 1954.4146 | M16: =L21/'[2]Data Entry'!$C$11/12 -> 2135.1119 | P16: =O21/'[2]Data Entry'!$C$11/12 -> 2316.8707 | S16: =R21/'[2]Data Entry'!$C$11/12 -> 2504.0822 | V16: =U21/'[2]Data Entry'!$C$11/12 -> 2579.2046 | Y16: =X21/'[2]Data Entry'!$C$11/12 -> 2656.5808 | AA16: =AA19/'[2]Data Entry'!$C$11/12 -> 2654.0939 | AC16: =AC19/'[2]Data Entry'!$C$11/12 -> 2707.1758 | AE16: =AE19/'[2]Data Entry'!$C$11/12 -> 2761.3193 | AG16: =AG19/'[2]Data Entry'!$C$11/12 -> 2816.5457 | AI16: =AI19/'[2]Data Entry'!$C$11/12 -> 2872.8766
B17: Average Annual Rent Increase | I17: 0 | M17: =(M16-I16)/I16 -> 0.09245596 | P17: =(P16-M16)/M16 -> 0.085128437 | S17: =(S16-P16)/P16 -> 0.080803606 | V17: =(V16-S16)/S16 -> 0.03 | Y17: =(Y16-V16)/V16 -> 0.03 | AA17: =(AA16-Y16)/Y16 -> -0.00093611671 | AC17: =(AC16-AA16)/AA16 -> 0.02 | AE17: =(AE16-AC16)/AC16 -> 0.02 | AG17: =(AG16-AE16)/AE16 -> 0.02 | AI17: =(AI16-AG16)/AG16 -> 0.02
B18: INCOME:
B19: Gross Rent | C19: ='IS (Combined)'!D12+'IS (Combined)'!D13 -> 899671.81 | D19: =+C19/$C$85 -> 0.97992857 | E19: =(I19/4)*2 -> 1002330 | F19: =+E19/$E$85 -> 1.0585217 | G19: =C19-E19 -> -102658.19 | I19: ='[2]Rent Analysis'!I23 -> 2004660 | J19: =+I19/'[2]Data Entry'!$C$11 -> 24447.073 | K19: =+I19/$I$85 -> 1.0585217 | L19: ='[2]Rent Analysis'!M23 -> 2274900 | M19: =+L19/'[2]Data Entry'!$C$11 -> 27742.683 | N19: =+L19/$L$85 -> 1.0772745 | O19: =+L19*(1+$L$7) -> 2343147 | P19: =+O19/'[2]Data Entry'!$C$11 -> 28574.963 | Q19: =+O19/$O$85 -> 1.0056618 | R19: =+O19*(1+$L$7) -> 2413441.4 | S19: =+R19/'[2]Data Entry'!$C$11 -> 29432.212 | T19: =+R19/$R$85 -> 0.96407555 | U19: =+R19*(1+$L$7) -> 2485844.7 | V19: =+U19/'[2]Data Entry'!$C$11 -> 30315.179 | W19: =+U19/$U$85 -> 0.96566226 | X19: =+U19*(1+$L$7) -> 2560420 | Y19: =+X19/'[2]Data Entry'!$C$11 -> 31224.634 | Z19: =+X19/$X$85 -> 0.96722323 | AA19: =X19*1.02 -> 2611628.4 | AB19: =AA19/$X$85 -> 0.9865677 | AC19: =AA19*1.02 -> 2663861 | AD19: =AC19/$X$85 -> 1.0062991 | AE19: =AC19*1.02 -> 2717138.2 | AF19: =AE19/$X$85 -> 1.026425 | AG19: =AE19*1.02 -> 2771480.9 | AH19: =AG19/$X$85 -> 1.0469535 | AI19: =AG19*1.02 -> 2826910.6 | AJ19: =AI19/$X$85 -> 1.0678926
B20: (Loss) / Gain to Old Lease | C20: 0 | D20: =+C20/$C$85 -> 0 | E20: =I20/2 -> -40758 | F20: =+E20/$E$85 -> -0.043042936 | G20: =C20-E20 -> 40758 | I20: ='[2]Rent Analysis'!G23-I19 -> -81516 | J20: =+I20/'[2]Data Entry'!$C$11 -> -994.09756 | K20: =+I20/$I$85 -> -0.043042936 | L20: =-L19+'[2]Rent Analysis'!M36 -> -173949.88 | M20: =+L20/'[2]Data Entry'!$C$11 -> -2121.3399 | N20: =+L20/$L$85 -> -0.082373631 | O20: =-O19+'[2]Rent Analysis'!M37 -> -63346.274 | P20: =+O20/'[2]Data Entry'!$C$11 -> -772.51553 | Q20: =+O20/$O$85 -> -0.027187763 | R20: =-R19+'[2]Rent Analysis'!M38 -> 50575.436 | S20: =+R20/'[2]Data Entry'!$C$11 -> 616.7736 | T20: =+R20/$R$85 -> 0.020202911 | U20: =-U19+'[2]Rent Analysis'!M39 -> 52092.699 | V20: =+U20/'[2]Data Entry'!$C$11 -> 635.27681 | W20: =+U20/$U$85 -> 0.020236161 | X20: =-X19+'[2]Rent Analysis'!M40 -> 53655.48 | Y20: =+X20/'[2]Data Entry'!$C$11 -> 654.33512 | Z20: =+X20/$X$85 -> 0.020268873 | AA20: =-AA19*0.01 -> -26116.284 | AB20: =AA20/$X$85 -> -0.009865677 | AC20: =-AC19*0.01 -> -26638.61 | AD20: =AC20/$X$85 -> -0.010062991 | AE20: =-AE19*0.01 -> -27171.382 | AF20: =AE20/$X$85 -> -0.01026425 | AG20: =-AG19*0.01 -> -27714.809 | AH20: =AG20/$X$85 -> -0.010469535 | AI20: =-AI19*0.01 -> -28269.106 | AJ20: =AI20/$X$85 -> -0.010678926
B21: Gross Possible Rent | C21: =SUM(C19:C20) -> 899671.81 | D21: =+C21/$C$85 -> 0.97992857 | E21: =SUM(E19:E20) -> 961572 | F21: =+E21/$E$85 -> 1.0154787 | G21: =SUM(G19:G20) -> -61900.19 | I21: =SUM(I19:I20) -> 1923144 | J21: =+I21/'[2]Data Entry'!$C$11 -> 23452.976 | K21: =+I21/$I$85 -> 1.0154787 | L21: =SUM(L19:L20) -> 2100950.1 | M21: =+L21/'[2]Data Entry'!$C$11 -> 25621.343 | N21: =+L21/$L$85 -> 0.99490091 | O21: =SUM(O19:O20) -> 2279800.7 | P21: =+O21/'[2]Data Entry'!$C$11 -> 27802.448 | Q21: =+O21/$O$85 -> 0.97847401 | R21: =SUM(R19:R20) -> 2464016.8 | S21: 26539 | T21: =+R21/$R$85 -> 0.98427846 | U21: =SUM(U19:U20) -> 2537937.4 | V21: 26539 | W21: =+U21/$U$85 -> 0.98589842 | X21: =SUM(X19:X20) -> 2614075.5 | Y21: 26539 | Z21: =+X21/$X$85 -> 0.98749211
B22: Deductions
B23: Bad Debt | C23: ='IS (Combined)'!D14 -> -54228.32 | D23: =+C23/$C$85 -> -0.05906585 | E23: =I23/2 -> -19231.44 | F23: =+E23/$E$85 -> -0.020309575 | G23: =C23-E23 -> -34996.88 | I23: =-$L$4*I21 -> -38462.88 | J23: =+I23/'[2]Data Entry'!$C$11 -> -469.05951 | K23: =+I23/$I$85 -> -0.020309575 | L23: =-$L$4*L21 -> -42019.002 | M23: =+L23/'[2]Data Entry'!$C$11 -> -512.42686 | N23: =+L23/$L$85 -> -0.019898018 | O23: =-$L$4*O21 -> -45596.015 | P23: =+O23/'[2]Data Entry'!$C$11 -> -556.04896 | Q23: =+O23/$O$85 -> -0.01956948 | R23: =-$L$4*R21 -> -49280.337 | S23: =+R23/'[2]Data Entry'!$C$11 -> -600.97972 | T23: =+R23/$R$85 -> -0.019685569 | U23: =-$L$4*U21 -> -50758.747 | V23: =+U23/'[2]Data Entry'!$C$11 -> -619.00911 | W23: =+U23/$U$85 -> -0.019717968 | X23: =-$L$4*X21 -> -52281.509 | Y23: =+X23/'[2]Data Entry'!$C$11 -> -637.57938 | Z23: =+X23/$X$85 -> -0.019749842
B24: Vacancy Loss | C24: 0 | D24: =+C24/$C$85 -> 0 | E24: =I24/2 -> -48078.6 | F24: =+E24/$E$85 -> -0.050773936 | G24: =C24-E24 -> 48078.6 | I24: =-$L$3*I21 -> -96157.2 | J24: =+I24/'[2]Data Entry'!$C$11 -> -1172.6488 | K24: =+I24/$I$85 -> -0.050773936 | L24: =-$L$3*L21 -> -105047.51 | M24: =+L24/'[2]Data Entry'!$C$11 -> -1281.0671 | N24: =+L24/$L$85 -> -0.049745046 | O24: =-$L$3*O21 -> -113990.04 | P24: =+O24/'[2]Data Entry'!$C$11 -> -1390.1224 | Q24: =+O24/$O$85 -> -0.0489237 | R24: =-$L$3*R21 -> -123200.84 | S24: =+R24/'[2]Data Entry'!$C$11 -> -1502.4493 | T24: =+R24/$R$85 -> -0.049213923 | U24: =-$L$3*U21 -> -126896.87 | V24: =+U24/'[2]Data Entry'!$C$11 -> -1547.5228 | W24: =+U24/$U$85 -> -0.049294921 | X24: =-$L$3*X21 -> -130703.77 | Y24: =+X24/'[2]Data Entry'!$C$11 -> -1593.9485 | Z24: =+X24/$X$85 -> -0.049374605
B25: Vacancy Loss - Model Units | C25: 0 | D25: =+C25/$C$85 -> 0 | E25: =I25/2 -> 0 | F25: =+E25/$E$85 -> 0 | G25: =C25-E25 -> 0 | I25: 0 | J25: =+I25/'[2]Data Entry'!$C$11 -> 0 | K25: =+I25/$I$85 -> 0 | L25: =+I25 -> 0 | M25: =+L25/'[2]Data Entry'!$C$11 -> 0 | N25: =+L25/$L$85 -> 0 | O25: =+L25*(1+$L$7) -> 0 | P25: =+O25/'[2]Data Entry'!$C$11 -> 0 | Q25: =+O25/$O$85 -> 0 | R25: =+O25*(1+$L$7) -> 0 | S25: =+R25/'[2]Data Entry'!$C$11 -> 0 | T25: =+R25/$R$85 -> 0 | U25: =+R25*(1+$L$7) -> 0 | V25: =+U25/'[2]Data Entry'!$C$11 -> 0 | W25: =+U25/$U$85 -> 0 | X25: =+U25*(1+$L$7) -> 0 | Y25: =+X25/'[2]Data Entry'!$C$11 -> 0 | Z25: =+X25/$X$85 -> 0
B26: Rent Concessions - Recurring | C26: 0 | D26: =+C26/$C$85 -> 0 | E26: =I26/2 -> 0 | F26: =+E26/$E$85 -> 0 | G26: =C26-E26 -> 0 | I26: =-$L$5*I21 -> 0 | J26: =+I26/'[2]Data Entry'!$C$11 -> 0 | K26: =+I26/$I$85 -> 0 | L26: =-$L$5*L21 -> 0 | M26: =+L26/'[2]Data Entry'!$C$11 -> 0 | N26: =+L26/$L$85 -> 0 | O26: =-$L$5*O21 -> 0 | P26: =+O26/'[2]Data Entry'!$C$11 -> 0 | Q26: =+O26/$O$85 -> 0 | R26: =-$L$5*R21 -> 0 | S26: =+R26/'[2]Data Entry'!$C$11 -> 0 | T26: =+R26/$R$85 -> 0 | U26: =-$L$5*U21 -> 0 | V26: =+U26/'[2]Data Entry'!$C$11 -> 0 | W26: =+U26/$U$85 -> 0 | X26: =-$L$5*X21 -> 0 | Y26: =+X26/'[2]Data Entry'!$C$11 -> 0 | Z26: =+X26/$X$85 -> 0
B27: Rent Concessions - One Time | C27: ='IS (Combined)'!D15 -> -15129.85 | D27: =+C27/$C$85 -> -0.016479534 | E27: =I27/2 -> 0 | F27: =+E27/$E$85 -> 0 | G27: =C27-E27 -> -15129.85 | I27: 0 | J27: =+I27/'[2]Data Entry'!$C$11 -> 0 | K27: =+I27/$I$85 -> 0 | L27: 0 | M27: =+L27/'[2]Data Entry'!$C$11 -> 0 | N27: =+L27/$L$85 -> 0 | O27: 0 | P27: =+O27/'[2]Data Entry'!$C$11 -> 0 | Q27: =+O27/$O$85 -> 0 | R27: 0 | S27: =+R27/'[2]Data Entry'!$C$11 -> 0 | T27: =+R27/$R$85 -> 0 | U27: =+R27 -> 0 | V27: =+U27/'[2]Data Entry'!$C$11 -> 0 | W27: =+U27/$U$85 -> 0 | X27: =+U27 -> 0 | Y27: =+X27/'[2]Data Entry'!$C$11 -> 0 | Z27: =+X27/$X$85 -> 0
B28: Employee Apartment Discounts | C28: 0 | D28: =+C28/$C$85 -> 0 | E28: =I28/2 -> 0 | F28: =+E28/$E$85 -> 0 | G28: =C28-E28 -> 0 | I28: 0 | J28: =+I28/'[2]Data Entry'!$C$11 -> 0 | K28: =+I28/$I$85 -> 0 | L28: =+I28 -> 0 | M28: =+L28/'[2]Data Entry'!$C$11 -> 0 | N28: =+L28/$L$85 -> 0 | O28: =+L28 -> 0 | P28: =+O28/'[2]Data Entry'!$C$11 -> 0 | Q28: =+O28/$O$85 -> 0 | R28: 0 | S28: =+R28/'[2]Data Entry'!$C$11 -> 0 | T28: =+R28/$R$85 -> 0 | U28: 0 | V28: =+U28/'[2]Data Entry'!$C$11 -> 0 | W28: =+U28/$U$85 -> 0 | X28: 0 | Y28: =+X28/'[2]Data Entry'!$C$11 -> 0 | Z28: =+X28/$X$85 -> 0
B29: Other | C29: 0 | D29: =+C29/$C$85 -> 0 | E29: =I29/2 -> 0 | F29: =+E29/$E$85 -> 0 | G29: =C29-E29 -> 0 | I29: 0 | J29: =+I29/'[2]Data Entry'!$C$11 -> 0 | K29: =+I29/$I$85 -> 0 | L29: 0 | M29: =+L29/'[2]Data Entry'!$C$11 -> 0 | N29: =+L29/$L$85 -> 0 | O29: 0 | P29: =+O29/'[2]Data Entry'!$C$11 -> 0 | Q29: =+O29/$O$85 -> 0 | R29: 0 | S29: =+R29/'[2]Data Entry'!$C$11 -> 0 | T29: =+R29/$R$85 -> 0 | U29: 0 | V29: =+U29/'[2]Data Entry'!$C$11 -> 0 | X29: 0 | Y29: =+X29/'[2]Data Entry'!$C$11 -> 0 | Z29: =+X29/$X$85 -> 0
B30: Other | C30: 0 | D30: =+C30/$C$85 -> 0 | E30: =I30/2 -> 0 | F30: =+E30/$E$85 -> 0 | G30: =C30-E30 -> 0 | I30: 0 | J30: =+I30/'[2]Data Entry'!$C$11 -> 0 | K30: =+I30/$I$85 -> 0 | L30: 0 | M30: =+L30/'[2]Data Entry'!$C$11 -> 0 | N30: =+L30/$L$85 -> 0 | O30: 0 | P30: =+O30/'[2]Data Entry'!$C$11 -> 0 | Q30: =+O30/$O$85 -> 0 | R30: 0 | S30: =+R30/'[2]Data Entry'!$C$11 -> 0 | T30: =+R30/$R$85 -> 0 | U30: 0 | V30: =+U30/'[2]Data Entry'!$C$11 -> 0 | X30: 0 | Y30: =+X30/'[2]Data Entry'!$C$11 -> 0 | Z30: =+X30/$X$85 -> 0
B31: Other | C31: 0 | D31: =+C31/$C$85 -> 0 | E31: =I31/2 -> 0 | F31: =+E31/$E$85 -> 0 | G31: =C31-E31 -> 0 | I31: 0 | J31: =+I31/'[2]Data Entry'!$C$11 -> 0 | K31: =+I31/$I$85 -> 0 | L31: 0 | M31: =+L31/'[2]Data Entry'!$C$11 -> 0 | N31: =+L31/$L$85 -> 0 | O31: 0 | P31: =+O31/'[2]Data Entry'!$C$11 -> 0 | Q31: =+O31/$O$85 -> 0 | R31: 0 | S31: =+R31/'[2]Data Entry'!$C$11 -> 0 | T31: =+R31/$R$85 -> 0 | U31: 0 | V31: =+U31/'[2]Data Entry'!$C$11 -> 0 | X31: 0 | Y31: =+X31/'[2]Data Entry'!$C$11 -> 0 | Z31: =+X31/$X$85 -> 0
B32: Other | C32: 0 | D32: =+C32/$C$85 -> 0 | E32: =I32/2 -> 0 | F32: =+E32/$E$85 -> 0 | G32: =C32-E32 -> 0 | I32: 0 | J32: =+I32/'[2]Data Entry'!$C$11 -> 0 | K32: =+I32/$I$85 -> 0 | L32: 0 | M32: =+L32/'[2]Data Entry'!$C$11 -> 0 | N32: =+L32/$L$85 -> 0 | O32: 0 | P32: =+O32/'[2]Data Entry'!$C$11 -> 0 | Q32: =+O32/$O$85 -> 0 | R32: 0 | S32: =+R32/'[2]Data Entry'!$C$11 -> 0 | T32: =+R32/$R$85 -> 0 | U32: 0 | V32: =+U32/'[2]Data Entry'!$C$11 -> 0 | W32: =+U32/$U$85 -> 0 | X32: 0 | Y32: =+X32/'[2]Data Entry'!$C$11 -> 0 | Z32: =+X32/$X$85 -> 0
B33: Total Deductions | C33: =SUM(C22:C32) -> -69358.17 | D33: =+C33/$C$85 -> -0.075545384 | E33: =SUM(E22:E32) -> -67310.04 | F33: =+E33/$E$85 -> -0.071083511 | G33: =SUM(G22:G32) -> -2048.13 | I33: =SUM(I22:I32) -> -134620.08 | J33: =+I33/'[2]Data Entry'!$C$11 -> -1641.7083 | K33: =+I33/$I$85 -> -0.071083511 | L33: =SUM(L22:L32) -> -147066.51 | M33: =+L33/'[2]Data Entry'!$C$11 -> -1793.494 | N33: =+L33/$L$85 -> -0.069643064 | O33: =SUM(O22:O32) -> -159586.05 | P33: =+O33/'[2]Data Entry'!$C$11 -> -1946.1714 | Q33: =+O33/$O$85 -> -0.06849318 | R33: =SUM(R22:R32) -> -172481.18 | S33: =+R33/'[2]Data Entry'!$C$11 -> -2103.429 | T33: =+R33/$R$85 -> -0.068899492 | U33: =SUM(U22:U32) -> -177655.61 | V33: =+U33/'[2]Data Entry'!$C$11 -> -2166.5319 | W33: =+U33/$U$85 -> -0.069012889 | X33: =SUM(X22:X32) -> -182985.28 | Y33: =+X33/'[2]Data Entry'!$C$11 -> -2231.5278 | Z33: =+X33/$X$85 -> -0.069124447
B34: Net Rental Income | C34: =+C21+C33 -> 830313.64 | D34: =+C34/$C$85 -> 0.90438318 | E34: =+E21+E33 -> 894261.96 | F34: =+E34/$E$85 -> 0.94439522 | G34: =+G21+G33 -> -63948.32 | I34: =+I21+I33 -> 1788523.9 | J34: =+I34/'[2]Data Entry'!$C$11 -> 21811.267 | K34: =+I34/$I$85 -> 0.94439522 | L34: =+L21+L33 -> 1953883.6 | M34: =+L34/'[2]Data Entry'!$C$11 -> 23827.849 | N34: =+L34/$L$85 -> 0.92525785 | O34: =+O21+O33 -> 2120214.7 | P34: =+O34/'[2]Data Entry'!$C$11 -> 25856.277 | Q34: =+O34/$O$85 -> 0.90998083 | R34: =+R21+R33 -> 2291535.7 | S34: =+R34/'[2]Data Entry'!$C$11 -> 27945.557 | T34: =+R34/$R$85 -> 0.91537897 | U34: =+U21+U33 -> 2360281.7 | V34: =+U34/'[2]Data Entry'!$C$11 -> 28783.924 | W34: =+U34/$U$85 -> 0.91688553 | X34: =+X21+X33 -> 2431090.2 | Y34: =+X34/'[2]Data Entry'!$C$11 -> 29647.441 | Z34: =+X34/$X$85 -> 0.91836766
B36: Other Income
B37: Administrative Fees | C37: 0 | D37: =+C37/$C$85 -> 0 | E37: =I37/2 -> 0 | F37: =+E37/$E$85 -> 0 | G37: =C37-E37 -> 0 | I37: 0 | J37: =+I37/'[2]Data Entry'!$C$11 -> 0 | K37: =+I37/$I$85 -> 0 | L37: =+I37*(1+$L$8) -> 0 | M37: =+L37/'[2]Data Entry'!$C$11 -> 0 | N37: =+L37/$L$85 -> 0 | O37: =+L37*(1+$L$8) -> 0 | P37: =+O37/'[2]Data Entry'!$C$11 -> 0 | Q37: =+O37/$O$85 -> 0 | R37: =+O37*(1+$L$8) -> 0 | S37: =+R37/'[2]Data Entry'!$C$11 -> 0 | T37: =+R37/$R$85 -> 0 | U37: =+R37*(1+$L$8) -> 0 | V37: =+U37/'[2]Data Entry'!$C$11 -> 0 | W37: =+U37/$U$85 -> 0 | X37: =+U37*(1+$L$8) -> 0 | Y37: =+X37/'[2]Data Entry'!$C$11 -> 0 | Z37: =+X37/$X$85 -> 0
B38: Alarm Charges | C38: 0 | D38: =+C38/$C$85 -> 0 | E38: =I38/2 -> 0 | F38: =+E38/$E$85 -> 0 | G38: =C38-E38 -> 0 | I38: 0 | J38: =+I38/'[2]Data Entry'!$C$11 -> 0 | K38: =+I38/$I$85 -> 0 | L38: =+I38*(1+$L$8) -> 0 | M38: =+L38/'[2]Data Entry'!$C$11 -> 0 | N38: =+L38/$L$85 -> 0 | O38: =+L38*(1+$L$8) -> 0 | P38: =+O38/'[2]Data Entry'!$C$11 -> 0 | Q38: =+O38/$O$85 -> 0 | R38: =+O38*(1+$L$8) -> 0 | S38: =+R38/'[2]Data Entry'!$C$11 -> 0 | T38: =+R38/$R$85 -> 0 | U38: =+R38*(1+$L$8) -> 0 | V38: =+U38/'[2]Data Entry'!$C$11 -> 0 | W38: =+U38/$U$85 -> 0 | X38: =+U38*(1+$L$8) -> 0 | Y38: =+X38/'[2]Data Entry'!$C$11 -> 0 | Z38: =+X38/$X$85 -> 0
B39: Appliance Rental Income | C39: 0 | D39: =+C39/$C$85 -> 0 | E39: =I39/2 -> 0 | F39: =+E39/$E$85 -> 0 | G39: =C39-E39 -> 0 | I39: 0 | J39: =+I39/'[2]Data Entry'!$C$11 -> 0 | K39: =+I39/$I$85 -> 0 | L39: =+I39*(1+$L$8) -> 0 | M39: =+L39/'[2]Data Entry'!$C$11 -> 0 | N39: =+L39/$L$85 -> 0 | O39: =+L39*(1+$L$8) -> 0 | P39: =+O39/'[2]Data Entry'!$C$11 -> 0 | Q39: =+O39/$O$85 -> 0 | R39: =+O39*(1+$L$8) -> 0 | S39: =+R39/'[2]Data Entry'!$C$11 -> 0 | T39: =+R39/$R$85 -> 0 | U39: =+R39*(1+$L$8) -> 0 | V39: =+U39/'[2]Data Entry'!$C$11 -> 0 | W39: =+U39/$U$85 -> 0 | X39: =+U39*(1+$L$8) -> 0 | Y39: =+X39/'[2]Data Entry'!$C$11 -> 0 | Z39: =+X39/$X$85 -> 0
B40: Application Fees | C40: ='IS (Combined)'!D22 -> 1350 | D40: =+C40/$C$85 -> 0.0014704291 | E40: =I40/2 -> 0 | F40: =+E40/$E$85 -> 0 | G40: =C40-E40 -> 1350 | I40: 0 | J40: =+I40/'[2]Data Entry'!$C$11 -> 0 | K40: =+I40/$I$85 -> 0 | L40: =+I40*(1+$L$8) -> 0 | M40: =+L40/'[2]Data Entry'!$C$11 -> 0 | N40: =+L40/$L$85 -> 0 | O40: =+L40*(1+$L$8) -> 0 | P40: =+O40/'[2]Data Entry'!$C$11 -> 0 | Q40: =+O40/$O$85 -> 0 | R40: =+O40*(1+$L$8) -> 0 | S40: =+R40/'[2]Data Entry'!$C$11 -> 0 | T40: =+R40/$R$85 -> 0 | U40: =+R40*(1+$L$8) -> 0 | V40: =+U40/'[2]Data Entry'!$C$11 -> 0 | W40: =+U40/$U$85 -> 0 | X40: =+U40*(1+$L$8) -> 0 | Y40: =+X40/'[2]Data Entry'!$C$11 -> 0 | Z40: =+X40/$X$85 -> 0
B41: Attorney / Court Fees | C41: ='IS (Combined)'!D19 -> 2780.92 | D41: =+C41/$C$85 -> 0.0030289967 | E41: =I41/2 -> 233 | F41: =+E41/$E$85 -> 0.00024606222 | G41: =C41-E41 -> 2547.92 | I41: 466 | J41: =+I41/'[2]Data Entry'!$C$11 -> 5.6829268 | K41: =+I41/$I$85 -> 0.00024606222 | L41: =+I41*(1+$L$8) -> 470.66 | M41: =+L41/'[2]Data Entry'!$C$11 -> 5.7397561 | N41: =+L41/$L$85 -> 0.00022288014 | O41: =+L41*(1+$L$8) -> 475.3666 | P41: =+O41/'[2]Data Entry'!$C$11 -> 5.7971537 | Q41: =+O41/$O$85 -> 0.00020402391 | R41: =+O41*(1+$L$8) -> 480.12027 | S41: =+R41/'[2]Data Entry'!$C$11 -> 5.8551252 | T41: =+R41/$R$85 -> 0.00019178929 | U41: =+R41*(1+$L$8) -> 484.92147 | V41: =+U41/'[2]Data Entry'!$C$11 -> 5.9136764 | W41: =+U41/$U$85 -> 0.00018837475 | X41: =+U41*(1+$L$8) -> 489.77068 | Y41: =+X41/'[2]Data Entry'!$C$11 -> 5.9728132 | Z41: =+X41/$X$85 -> 0.00018501558
B42: Bad Debt Recovery | C42: 0 | D42: =+C42/$C$85 -> 0 | E42: =I42/2 -> 0 | F42: =+E42/$E$85 -> 0 | G42: =C42-E42 -> 0 | I42: 0 | J42: =+I42/'[2]Data Entry'!$C$11 -> 0 | K42: =+I42/$I$85 -> 0 | L42: =+I42*(1+$L$8) -> 0 | M42: =+L42/'[2]Data Entry'!$C$11 -> 0 | N42: =+L42/$L$85 -> 0 | O42: =+L42*(1+$L$8) -> 0 | P42: =+O42/'[2]Data Entry'!$C$11 -> 0 | Q42: =+O42/$O$85 -> 0 | R42: =+O42*(1+$L$8) -> 0 | S42: =+R42/'[2]Data Entry'!$C$11 -> 0 | T42: =+R42/$R$85 -> 0 | U42: =+R42*(1+$L$8) -> 0 | V42: =+U42/'[2]Data Entry'!$C$11 -> 0 | W42: =+U42/$U$85 -> 0 | X42: =+U42*(1+$L$8) -> 0 | Y42: =+X42/'[2]Data Entry'!$C$11 -> 0 | Z42: =+X42/$X$85 -> 0
B43: Cable Fees (Access & Marketing) | C43: 0 | D43: =+C43/$C$85 -> 0 | E43: =I43/2 -> 0 | F43: =+E43/$E$85 -> 0 | G43: =C43-E43 -> 0 | I43: 0 | J43: =+I43/'[2]Data Entry'!$C$11 -> 0 | K43: =+I43/$I$85 -> 0 | L43: =+I43*(1+$L$8) -> 0 | M43: =+L43/'[2]Data Entry'!$C$11 -> 0 | N43: =+L43/$L$85 -> 0 | O43: =+L43*(1+$L$8) -> 0 | P43: =+O43/'[2]Data Entry'!$C$11 -> 0 | Q43: =+O43/$O$85 -> 0 | R43: =+O43*(1+$L$8) -> 0 | S43: =+R43/'[2]Data Entry'!$C$11 -> 0 | T43: =+R43/$R$85 -> 0 | U43: =+R43*(1+$L$8) -> 0 | V43: =+U43/'[2]Data Entry'!$C$11 -> 0 | W43: =+U43/$U$85 -> 0 | X43: =+U43*(1+$L$8) -> 0 | Y43: =+X43/'[2]Data Entry'!$C$11 -> 0 | Z43: =+X43/$X$85 -> 0
B44: Clubhouse or Facility Rental | C44: 0 | D44: =+C44/$C$85 -> 0 | E44: =I44/2 -> 0 | F44: =+E44/$E$85 -> 0 | G44: =C44-E44 -> 0 | I44: 0 | J44: =+I44/'[2]Data Entry'!$C$11 -> 0 | K44: =+I44/$I$85 -> 0 | L44: =+I44*(1+$L$8) -> 0 | M44: =+L44/'[2]Data Entry'!$C$11 -> 0 | N44: =+L44/$L$85 -> 0 | O44: =+L44*(1+$L$8) -> 0 | P44: =+O44/'[2]Data Entry'!$C$11 -> 0 | Q44: =+O44/$O$85 -> 0 | R44: =+O44*(1+$L$8) -> 0 | S44: =+R44/'[2]Data Entry'!$C$11 -> 0 | T44: =+R44/$R$85 -> 0 | U44: =+R44*(1+$L$8) -> 0 | V44: =+U44/'[2]Data Entry'!$C$11 -> 0 | W44: =+U44/$U$85 -> 0 | X44: =+U44*(1+$L$8) -> 0 | Y44: =+X44/'[2]Data Entry'!$C$11 -> 0 | Z44: =+X44/$X$85 -> 0
...

Sheet BS & IS (Combined)
A1: Allaire on 41st top level
A2: Unaudited Consolidated Balance Sheet
A3: As of 9/30/2025
A6: ASSETS
A7: Cash and Cash Equivalents | B7: ='TB Combined'!H5+'TB Combined'!H6 -> 1178469.8
A8: Accounts Receivable | B8: ='TB Combined'!H7 -> 49276.86
A9: Prepaid Insurance | B9: ='TB Combined'!H10 -> 60248.17
A10: Prepaid Interest | B10: ='TB Combined'!H11 -> 0
A11: Prepaid Other | B11: ='TB Combined'!H12 -> 0
A12: Fixed Assets, Net | B12: ='TB Combined'!H13 -> 17627868
A13: Capitalized Loan Costs, Net | B13: ='TB Combined'!H14 -> 168204.2
A14: Deposits in Escrow | B14: ='TB Combined'!H15 -> 99209.46
A15: Property Tax in Escrow | B15: ='TB Combined'!H16 -> 215081.24
A16: Other Assets | B16: ='TB Combined'!H17 -> 0
A17: TOTAL ASSETS | B17: =SUM(B7:B16) -> 19398358
A19: LIABILITIES AND EQUITY
A20: Liabilities
A21: Accounts Payable | B21: =-'TB Combined'!H18-'TB Combined'!H19 -> 20779.49
A22: Security Deposits | B22: =-'TB Combined'!H8-'TB Combined'!H9 -> 110900.39
A23: Property Taxes Payable | B23: =-'TB Combined'!H20 -> 177461.29
A24: Management Fee Payable | B24: =-'TB Combined'!H21 -> 36450
A25: Notes Payable | B25: =-'TB Combined'!H22 -> 12180000
A26: Other Liabilities
A27: Total Liabilities | B27: =SUM(B21:B26) -> 12525591
A28: Equity
A29: Members Equity | B29: =-'TB Combined'!H23 -> 7290000
A30: Current Year Net Income | B30: =B98 -> -363004.67
A31: Accumulated Earnings & Profits
A32: Total Equity | B32: =SUM(B29:B31) -> 6926995.3
A33: TOTAL LIABILITIES AND EQUITY | B33: =(B27)+(B32) -> 19452586
B36: =B33-B17 -> 54228.31
A41: =A1 -> Allaire on 41st top level
A42: Unaudited Consolidated Income Statement
A43: April 9, 2025 through September 30, 2025
A45: REVENUES
A46: Rent Income | B46: =-'TB Combined'!H25-'TB Combined'!H26-'TB Combined'!H27 -> 884541.96
A47: Other Income | B47: =-SUM('TB Combined'!H28:H44) -> 87785.74
A48: Gross Operating Profit | B48: =SUM(B46:B47) -> 972327.7
A50: Supplies - Cleaning and Maitenance | B50: =-'TB Combined'!H47-'TB Combined'!H46 -> -339.91
A51: Cleaning and Maintenance -Other | B51: =-'TB Combined'!H48 -> -9139.9
...

Sheet IS (Combined)
A1: Income Statement
A2: As of: Sept 2025
A3: Accounting Basis: Accrual
A4: Level of Detail: Detail View
A5: Include Zero Balance GL Accounts: No
B7: Quarter Ended | C7: Year to Date
A8: Account Name | B8: 45930 | C8: 45930 | D8: Since Inception
A9: Operating Income & Expense
A10: Income
A11: RENTS
A12: Rent Income | B12: =C12-'IS (Combined) (Q2)'!B11 -> 447725.8 | C12: =D12 -> 895738.81 | D12: =-'TB Combined'!H25 -> 895738.81
A13: Section 8 Rent | B13: =C13-'IS (Combined) (Q2)'!B12 -> 0 | C13: =D13 -> 3933 | D13: =-'TB Combined'!H26 -> 3933
A14: Bad debt | B14: =-'TB Combined'!H45 -> -54228.32 | C14: =D14 -> -54228.32 | D14: =-'TB Combined'!H45 -> -54228.32
A15: Concessions | B15: =C15-'IS (Combined) (Q2)'!B13 -> -14175 | C15: =D15 -> -15129.85 | D15: =-'TB Combined'!H27 -> -15129.85
A16: Total RENTS | B16: =SUM(B12:B15) -> 379322.48 | C16: =D16 -> 830313.64 | D16: =SUM(D12:D15) -> 830313.64
A17: FEES | C17: =D17 -> 0
A18: NSF/Returned Payment Fees | B18: =C18-'IS (Combined) (Q2)'!B16 -> 811.49 | C18: =D18 -> 1331.24 | D18: =-'TB Combined'!H28 -> 1331.24
A19: Tenant Eviction/Legal Recovery | B19: =C19-'IS (Combined) (Q2)'!B17 -> 1345.46 | C19: =D19 -> 2780.92 | D19: =-'TB Combined'!H29 -> 2780.92
A20: Pet Rent | B20: =C20-'IS (Combined) (Q2)'!B18 -> 80.32 | C20: =D20 -> 193.72 | D20: =-'TB Combined'!H30 -> 193.72
A21: 4430: Pet Fee-Non Refundable | B21: =C21 -> 236.25 | C21: =D21 -> 236.25 | D21: =-'TB Combined'!H31 -> 236.25
A22: Application Fee Income | B22: =C22-'IS (Combined) (Q2)'!B19 -> 967.5 | C22: =D22 -> 1350 | D22: =-'TB Combined'!H32 -> 1350
A23: 4445: Administration Fee | B23: =C23 -> 300.32 | C23: =D23 -> 300.32 | D23: =-'TB Combined'!H33 -> 300.32
A24: Insurance Services | B24: =C24-'IS (Combined) (Q2)'!B20 -> 2601.38 | C24: =D24 -> 5263.24 | D24: =-'TB Combined'!H34 -> 5263.24
A25: Insurance Admin Fees | B25: =C25-'IS (Combined) (Q2)'!B21 -> 51 | C25: =D25 -> 81 | D25: =-'TB Combined'!H35 -> 81
A26: Security Deposit Insurance | B26: =C26-'IS (Combined) (Q2)'!B22 -> 3050 | C26: =D26 -> 5300 | D26: =-'TB Combined'!H36 -> 5300
A27: Break Lease | B27: =C27-'IS (Combined) (Q2)'!B23 -> 14226.25 | C27: =D27 -> 17996.8 | D27: =-'TB Combined'!H37 -> 17996.8
A28: Late Fee | B28: =C28-'IS (Combined) (Q2)'!B24 -> 5318.69 | C28: =D28 -> 9473.42 | D28: =-'TB Combined'!H38 -> 9473.42
A29: Utility Reimbursement Fee | B29: =C29-'IS (Combined) (Q2)'!B25 -> 12585.35 | C29: =D29 -> 24467.27 | D29: =-'TB Combined'!H39 -> 24467.27
A30: Garbage Fee | B30: =C30-'IS (Combined) (Q2)'!B26 -> 3602.65 | C30: =D30 -> -221 | D30: =-'TB Combined'!H40 -> -221
A31: Total FEES | B31: =SUM(B18:B30) -> 45176.66 | C31: =D31 -> 68553.18 | D31: =SUM(D18:D30) -> 68553.18
A32: Deposit Forfeit | B32: =C32-'IS (Combined) (Q2)'!B28 -> 9350 | C32: =D32 -> 16760 | D32: =-'TB Combined'!H41 -> 16760
A33: Laundry Income | B33: =C33-'IS (Combined) (Q2)'!B29 -> 577.24 | C33: =D33 -> 849.56 | D33: =-'TB Combined'!H42 -> 849.56
A34: Tenant Improvements | B34: =C34-'IS (Combined) (Q2)'!B30 -> 233.5 | C34: =D34 -> 519.75 | D34: =-'TB Combined'!H43 -> 519.75
A35: Miscellaneous Income | B35: =C35-'IS (Combined) (Q2)'!B31 -> 94.5 | C35: =D35 -> 1103.25 | D35: =-'TB Combined'!H44 -> 1103.25
A36: Total Operating Income | B36: =SUM(B31:B35)+B16 -> 434754.38 | C36: =SUM(C31:C35)+C16 -> 918099.38 | D36: =SUM(D31:D35)+D16 -> 918099.38
A37: Expense
A38: CLEANING AND MAINTENANCE
A39: 6071: Carpet Cleaning | B39: =C39 -> 95 | C39: =D39 -> 95 | D39: ='TB Combined'!H46 -> 95
A40: Supplies - Cleaning and Maitenance | B40: =C40-'IS (Combined) (Q2)'!B35 -> 0 | C40: =D40 -> 244.91 | D40: ='TB Combined'!H47 -> 244.91
A41: Cleaning and Maintenance -Other | B41: =C41-'IS (Combined) (Q2)'!B36 -> 4700.61 | C41: =D41 -> 9139.9 | D41: ='TB Combined'!H48 -> 9139.9
...

Sheet CapEx
A3: CAPITAL EXPENSES
A4: Appliances | B4: 1395
A5: Remodel-Gen. Maintenance Labor | B5: 40859.39
A6: Remodel - Supplies | B6: 17886.5
A7: Remodel-Exterior Renovations | B7: 26529.17
A8: ='Fixed Assets'!C15 -> Units 123 and 114 - remodels | B8: ='Fixed Assets'!E15 -> 55382.62
A9: Drainage/Storm water | B9: ='Fixed Assets'!E17 -> 10221.09
A10: Total | B10: =SUM(B4:B9) -> 152273.77

Sheet Fund Exp
A4: Administrative | B4: ='TB Combined'!H78 -> 4275
A5: Acquisition Fees | B5: ='TB Combined'!H79 -> 344000
A6: Bank Fees | B6: ='TB Combined'!H80 -> 575
A7: Due Diligence | B7: ='TB Combined'!H81 -> 113505.01
A8: Guarantor Fee | B8: ='TB Combined'!H82 -> 100000
A9: Management Fees | B9: ='TB Combined'!H83 -> 70065.01
A10: Professional Fees | B10: ='TB Combined'!H84 -> 34448
A11: Other Costs | B11: ='TB Combined'!H85 -> 13210
A12: Interest Income | B12: ='TB Combined'!H86 -> -16082.44
A13: Loan Interest Expense | B13: ='TB Combined'!H87 -> 287481.82
A14: Related Party Interest Expense | B14: ='TB Combined'!H88 -> 8555.0596
A15: Amortization | B15: ='TB Combined'!H89 -> 8410.2
A16: Depreciation | B16: ='TB Combined'!H90 -> 0

Sheet Fixed Assets
A3: Asset | B3: Asset Type | C3: Details | D3: Acquisition date | E3: Purchase price | F3: life
A4: Building | D4: 45755
B5: Land | C5: Purchase price allocation | D5: =D4 -> 45755 | E5: 2050000 | F5: N/A
B6: Building | C6: Purchase price allocation | D6: =D5 -> 45755 | E6: 11817000 | F6: 27.5
B7: Equipment | C7: Purchase price allocation | D7: 45755 | E7: 2575500 | F7: 5
B8: Improvements | C8: Purchase price allocation | D8: =D6 -> 45755 | E8: 757500 | F8: 15
A10: Closing Costs | B10: Land | C10: Closing Costs Allocation | D10: =D8 -> 45755 | E10: =ROUND([3]Purchase!E58,2) -> 15950.67 | F10: N/A
B11: Building | C11: Closing Costs Allocation | D11: =D10 -> 45755 | E11: =ROUND([3]Purchase!E59,2) -> 91945.86 | F11: 27.5
B12: Equipment | C12: Closing Costs Allocation | D12: 45755 | E12: =ROUND([3]Purchase!E60,2) -> 20039.48 | F12: 5
B13: Improvements | C13: Closing Costs Allocation | D13: =D11 -> 45755 | E13: =ROUND([3]Purchase!E61,2) -> 5893.97 | F13: 15
A15: Improvements | C15: Units 123 and 114 - remodels | D15: 45755 | E15: 55382.62 | F15: 15
A16: Improvements | D16: 45772 | E16: 5000 | F16: 15
A17: Improvements | C17: Drainage | D17: ='[3]Bank Movements (Sorted) (2)'!E34 -> 45814 | E17: =-'[3]Bank Movements (Sorted) (2)'!H34 -> 10221.09 | F17: 15
A18: Improvements | D18: 45859 | E18: =-'[4]Movements Sorted Q3'!H13-'[4]Movements Sorted Q3'!H14 -> 16613.41 | F18: 15
A19: Improvements | D19: 45911 | E19: =-'[4]Movements Sorted Q3'!H9-'[4]Movements Sorted Q3'!H10 -> 16004.48 | F19: 15
A20: Improvements | E20: =SUM('TB Combined'!B73:B77) -> 199699.07 | F20: 15
A33: Total | E33: =SUM(E5:E32) -> 17636751

Sheet Cash Flow (Combined)
A1: Cash Flow
A3: Account Name | B3: Fiscal Year To Date | C3: Combined
A4: Operating Income & Expense
A5: Income
A6: RENTS
A7: Rent Income | B7: 346908.26 | C7: ='IS (Combined)'!D12 -> 895738.81
A8: Section 8 Rent | B8: 3933 | C8: ='IS (Combined)'!D13 -> 3933
A9: Concessions | B9: -954.85 | C9: ='IS (Combined)'!D15 -> -15129.85
A10: Total RENTS | B10: 349886.41 | C10: ='IS (Combined)'!D16 -> 830313.64
A11: FEES | C11: ='IS (Combined)'!D17 -> 0
A12: NSF/Returned Payment Fees | B12: 519.75 | C12: ='IS (Combined)'!D18 -> 1331.24
A13: Tenant Eviction/Legal Recovery | B13: 1435.46 | C13: ='IS (Combined)'!D19 -> 2780.92
A14: Pet Rent | B14: 113.4 | C14: ='IS (Combined)'!D20 -> 193.72
A15: Application Fee Income | B15: 382.5 | C15: ='IS (Combined)'!D22 -> 1350
A16: Insurance Services | B16: 2661.86 | C16: ='IS (Combined)'!D24 -> 5263.24
A17: Insurance Admin Fees | B17: 30 | C17: ='IS (Combined)'!D25 -> 81
A18: Security Deposit Insurance | B18: 2250 | C18: ='IS (Combined)'!D26 -> 5300
A19: Break Lease | B19: 3770.55 | C19: ='IS (Combined)'!D27 -> 17996.8
A20: Late Fee | B20: 4154.73 | C20: ='IS (Combined)'!D28 -> 9473.42
A21: Utility Reimbursement Fee | B21: 11881.92 | C21: ='IS (Combined)'!D29 -> 24467.27
A22: Garbage Fee | B22: -3823.65 | C22: ='IS (Combined)'!D30 -> -221
A23: Total FEES | B23: 23376.52 | C23: ='IS (Combined)'!D31 -> 68553.18
A24: Deposit Forfeit | B24: 7410 | C24: ='IS (Combined)'!D32 -> 16760
A25: Laundry Income | B25: 272.32 | C25: ='IS (Combined)'!D33 -> 849.56
A26: Tenant Improvements | B26: 286.25 | C26: ='IS (Combined)'!D34 -> 519.75
A27: Miscellaneous Income | B27: 1008.75 | C27: ='IS (Combined)'!D35 -> 1103.25
A28: Total Operating Income | B28: 382240.25 | C28: ='IS (Combined)'!D36 -> 918099.38
A29: Expense | C29: ='IS (Combined)'!D37 -> 0
A30: CLEANING AND MAINTENANCE | C30: ='IS (Combined)'!D38 -> 0
A31: Supplies - Cleaning and Maitenance | B31: 244.91 | C31: ='IS (Combined)'!D40 -> 244.91
A32: Cleaning and Maintenance -Other | B32: 4439.29 | C32: ='IS (Combined)'!D41 -> 9139.9
A33: Total CLEANING AND MAINTENANCE | B33: 4684.2 | C33: ='IS (Combined)'!D42 -> 9479.81
A34: Permits & Licenses | B34: 680.35 | C34: ='IS (Combined)'!D43 -> 1094.3
A35: CONTRACT SERVICES | C35: ='IS (Combined)'!D44 -> 0
A36: Elevator | B36: 270 | C36: ='IS (Combined)'!D45 -> 3770
A37: Pool | B37: 1475.76 | C37: ='IS (Combined)'!D46 -> 3117.08
A38: Pest Control | B38: 21.21 | C38: ='IS (Combined)'!D47 -> 173.35
A39: Landscaping | B39: 4353 | C39: ='IS (Combined)'!D48 -> 2743
A40: Total CONTRACT SERVICES | B40: 6119.97 | C40: ='IS (Combined)'!D49 -> 9803.43
A41: LEGAL AND OTHER PROFESSIONAL FEES | C41: ='IS (Combined)'!D50 -> 0
...

Sheet TB Combined
A1: Combined Trial Balance
A2: At 9-30-2025
A4: Account Name | B4: Year to Month End | D4: Top | F4: Eliminations | H4: Combined
A5: Operating Account | B5: 17506.83 | D5: ='Balance Sheet & IS'!B7 -> 1072818 | H5: =SUM(B5:G5) -> 1090324.8
A6: Security Account | B6: 88145 | H6: =SUM(B6:G6) -> 88145
A7: Accounts Receivable | B7: 103505.18 | D7: ='Balance Sheet & IS'!B8 -> 101712.79 | F7: =-D7-F45 -> -155941.11 | H7: =SUM(B7:G7) -> 49276.86
A8: Mgmt Held Security Deposits | B8: -92730 | H8: =SUM(B8:G8) -> -92730
A9: Prepaid Rent | B9: -18170.39 | H9: =SUM(B9:G9) -> -18170.39
A10: Prepaid Insurance | D10: ='Balance Sheet & IS'!B9 -> 60248.17 | H10: =SUM(B10:G10) -> 60248.17
A11: Prepaid Interest | D11: ='Balance Sheet & IS'!B10 -> 0 | H11: =SUM(B11:G11) -> 0
A12: Prepaid Other | D12: ='Balance Sheet & IS'!B11 -> 0 | H12: =SUM(B12:G12) -> 0
A13: Fixed Assets, Net | D13: ='Balance Sheet & IS'!B12 -> 17423169 | F13: =5000-SUM(F73:F77) -> 204699.07 | H13: =SUM(B13:G13) -> 17627868
A14: Capitalized Loan Costs, Net | D14: ='Balance Sheet & IS'!B13 -> 168204.2 | H14: =SUM(B14:G14) -> 168204.2
A15: Deposits in Escrow | D15: ='Balance Sheet & IS'!B14 -> 99209.46 | H15: =SUM(B15:G15) -> 99209.46
A16: Property Tax in Escrow | D16: ='Balance Sheet & IS'!B15 -> 215081.24 | H16: =SUM(B16:G16) -> 215081.24
A17: Other Assets | D17: ='Balance Sheet & IS'!B16 -> 0 | H17: =SUM(B17:G17) -> 0
A18: Accounts Payable | B18: -12124.33 | H18: =SUM(B18:G18) -> -12124.33
A19: Accounts Payable-Top | D19: =-'Balance Sheet & IS'!B21 -> -8655.1596 | H19: =SUM(B19:G19) -> -8655.1596
A20: Property Taxes Payable | D20: =-'Balance Sheet & IS'!B22 -> -177461.29 | H20: =SUM(B20:G20) -> -177461.29
A21: Management Fee Payable | D21: =-'Balance Sheet & IS'!B23 -> -36450 | H21: =SUM(B21:G21) -> -36450
A22: Notes Payable | D22: =-'Balance Sheet & IS'!B24 -> -12180000 | H22: =SUM(B22:G22) -> -12180000
A23: Owner Contribution | B23: -101712.79 | D23: =-'Balance Sheet & IS'!B28 -> -7290000 | F23: =-B23 -> 101712.79 | H23: =SUM(B23:G23) -> -7290000
A24: Owner Distribution | B24: 493060.47 | D24: =-'Balance Sheet & IS'!B47 -> -485533.47 | F24: =-F78-2527-5000 -> -7527 | H24: =SUM(B24:G24) -> 0
A25: Rent Income | B25: -794634.06 | D25: =-'Balance Sheet & IS'!B46 -> -101104.75 | H25: =SUM(B25:G25) -> -895738.81
A26: Section 8 Rent | B26: -3933 | H26: =SUM(B26:G26) -> -3933
A27: Concessions | B27: 15129.85 | H27: =SUM(B27:G27) -> 15129.85
A28: NSF/Returned Payment Fees | B28: -1331.24 | H28: =SUM(B28:G28) -> -1331.24
A29: Tenant Eviction/Legal Recovery | B29: -2780.92 | H29: =SUM(B29:G29) -> -2780.92
A30: Pet Rent | B30: -193.72 | H30: =SUM(B30:G30) -> -193.72
A31: 4430: Pet Fee-Non Refundable | B31: -236.25 | H31: =SUM(B31:G31) -> -236.25
A32: Application Fee Income | B32: -1350 | H32: =SUM(B32:G32) -> -1350
A33: 4445: Administration Fee | B33: -300.32 | H33: =SUM(B33:G33) -> -300.32
A34: Insurance Services | B34: -5263.24 | H34: =SUM(B34:G34) -> -5263.24
A35: Insurance Admin Fees | B35: -81 | H35: =SUM(B35:G35) -> -81
A36: Security Deposit Insurance | B36: -5300 | H36: =SUM(B36:G36) -> -5300
A37: Break Lease | B37: -17996.8 | H37: =SUM(B37:G37) -> -17996.8
... A44: Miscellaneous Income | B44: -1103.25 | H44: =SUM(B44:G44) -> -1103.25
A45: Bad Debt | F45: ='Bad Debt'!H19 -> 54228.32 | H45: =SUM(B45:G45) -> 54228.32
A46: 6071: Carpet Cleaning | B46: 95 | H46: =SUM(B46:G46) -> 95
A47: Supplies - Cleaning and Maitenance | B47: 244.91 | H47: =SUM(B47:G47) -> 244.91
...

Sheet IS
A1: Income Statement
A2: Exported On: 11/05/2025 09:20 PM
A4: Cruise Property Management
A5: Properties: Active
A6: As of: Sep 2025
A7: Accounting Basis: Accrual
A8: Level of Detail: Detail View
A9: Include Zero Balance GL Accounts: No
A11: Account Name | B11: Selected Month | C11: % of Selected Month | D11: Year to Month End | E11: % of Year to Month End
A12: Operating Income & Expense
A13: Income
A14: RENTS
A15: Rent Income | B15: 149866 | C15: 90.41 | D15: 794634.06 | E15: 91.21
A16: Section 8 Rent | B16: 0 | C16: 0 | D16: 3933 | E16: 0.45
A17: Concessions | B17: -4390 | C17: -2.65 | D17: -15129.85 | E17: -1.74
A18: Total RENTS | B18: 145476 | C18: 87.77 | D18: 783437.21 | E18: 89.92
A19: FEES
A20: NSF/Returned Payment Fees | B20: 282.12 | C20: 0.17 | D20: 1331.24 | E20: 0.15
A21: Tenant Eviction/Legal Recovery | B21: 0 | C21: 0 | D21: 2780.92 | E21: 0.32
A22: Pet Rent | B22: 42.52 | C22: 0.03 | D22: 193.72 | E22: 0.02
A23: Pet Fee-Non Refundable | B23: 236.25 | C23: 0.14 | D23: 236.25 | E23: 0.03
A24: Application Fee Income | B24: 292.5 | C24: 0.18 | D24: 1350 | E24: 0.15
A25: Administration Fee | B25: 25 | C25: 0.02 | D25: 300.32 | E25: 0.03
A26: Insurance Services | B26: 773.83 | C26: 0.47 | D26: 5263.24 | E26: 0.6
A27: Insurance Admin Fees | B27: 12.83 | C27: 0.01 | D27: 81 | E27: 0.01
A28: Security Deposit Insurance | B28: 900 | C28: 0.54 | D28: 5300 | E28: 0.61
A29: Break Lease | B29: 4315.5 | C29: 2.6 | D29: 17996.8 | E29: 2.07
A30: Late Fee | B30: 1235.54 | C30: 0.75 | D30: 9473.42 | E30: 1.09
A31: Utility Reimbursement Fee | B31: 4187.85 | C31: 2.53 | D31: 24467.27 | E31: 2.81
... A38: Total Operating Income | B38: 165754.27 | C38: 100 | D38: 871222.95 | E38: 100
A39: Expense
A40: CLEANING AND MAINTENANCE
A41: Carpet Cleaning | B41: 95 | C41: 0.06 | D41: 95 | E41: 0.01
A42: Supplies - Cleaning and Maitenance | B42: 0 | C42: 0 | D42: 244.91 | E42: 0.03
A43: Cleaning and Maintenance -Other | B43: 1638.7 | C43: 0.99 | D43: 9139.9 | E43: 1.05
A44: Total CLEANING AND MAINTENANCE | B44: 1733.7 | C44: 1.05 | D44: 9479.81 | E44: 1.09
A45: Permits & Licenses | B45: 51.5 | C45: 0.03 | D45: 1094.3 | E45: 0.13
A46: CONTRACT SERVICES
A47: Elevator | B47: 3500 | C47: 2.11 | D47: 3770 | E47: 0.43
A48: Pool | B48: 531.4 | C48: 0.32 | D48: 3117.08 | E48: 0.36
...

Sheet BS
A1: Balance Sheet
A2: Exported On: 10/14/2025 07:25 PM
A4: Properties: Active
A5: As of: 09/30/2025
A6: Accounting Basis: Accrual
A7: Level of Detail: Detail View
A8: Include Zero Balance GL Accounts: No
A10: Account Number | B10: Account Name | C10: Balance
B11: ASSETS
B12: Cash
A13: 1101 | B13: Operating Account | C13: 17506.83
A14: 1102 | B14: Security Account | C14: 88145
B15: Total Cash | C15: 105651.83
A16: 1300 | B16: Accounts Receivable | C16: 103505.18
B17: TOTAL ASSETS | C17: 209157.01
B20: LIABILITIES & CAPITAL
B21: Liabilities
B22: SECURITY DEPOSITS
A23: 2101 | B23: Mgmt Held Security Deposits | C23: 92730
B24: Total SECURITY DEPOSITS | C24: 92730
A25: 2300 | B25: Prepaid Rent | C25: 18170.39
A26: 2500 | B26: Accounts Payable | C26: 12094.77
B27: Total Liabilities | C27: 122995.16
B28: Capital
A29: 3150 | B29: Owner Contribution | C29: 101712.79
A30: 3250 | B30: Owner Distribution | C30: -418060.47
B31: Calculated Retained Earnings | C31: 402509.53
B32: Total Capital | C32: 86161.85
B33: TOTAL LIABILITIES & CAPITAL | C33: 209157.01

Sheet Bad Debt
A1: Unit | B1: Name | C1: Tenant Status | D1: Tags | E1: Phone Numbers | F1: Move In | G1: Move Out | H1: Amount Receivable | I1: Delinquent Subsidy Amount | J1: 0-30 | K1: 30+
A3: -> Allaire on 41st St - 5525 SW 41 St Pembroke Park, FL 33023
A4: 109 | B4: Joseph, Mannes | C4: Past | E4: Mobile: (786) 991-5452 | F4: 45717 | G4: 45838 | H4: 475 | I4: 0 | J4: 0 | K4: 475
A5: 118 | B5: Mitchell , Annmarie Marcia | C5: Past | E5: Home: (954) 901-6814 | F5: 45717 | G5: 45890 | H5: 10593.98 | I5: 0 | J5: 0 | K5: 10593.98
A6: 121 | B6: Zephir, Walando | C6: Past | E6: Phone: (754) 207-9389 | F6: 45717 | G6: 45838 | H6: 4300 | I6: 0 | J6: 0 | K6: 4300
A7: 122 | B7: Simms, Elizabeth | C7: Past | E7: Home: (754) 204-4281 | F7: 45717 | G7: 45900 | H7: 2687 | I7: 0 | J7: 2687 | K7: 0
A8: 124 | B8: Schieck, Todd | C8: Past | E8: Phone: (303) 993-9414 | F8: 45717 | G8: 45866 | H8: 175 | I8: 0 | J8: 0 | K8: 175
A9: 207 | B9: Brown, Tracy | C9: Past | E9: Home: (954) 391-0478 | F9: 45717 | G9: 45808 | H9: 780 | I9: 0 | J9: 0 | K9: 780
A10: 209 | B10: Pouncy, Shawn | C10: Past | D10: LeaseLock | F10: 45717 | G10: 45758 | H10: 12695.36 | I10: 0 | J10: 0 | K10: 12695.36
A11: 219 | B11: Hyacinthe, Albertha | C11: Past | E11: Home: (954) 483-5709 | F11: 45717 | G11: 45807 | H11: 940 | I11: 0 | J11: 0 | K11: 940
A12: 224 | B12: St-Armond, Geminiaya | C12: Past | E12: Phone: (786) 436-6053 | F12: 45717 | G12: 45885 | H12: 4269.5 | I12: 0 | J12: 0 | K12: 4269.5
A13: 305 | B13: Othelot, Aaliyah | C13: Past | E13: Home: (305) 509-9578 | F13: 45717 | G13: 45904 | H13: 165 | I13: 0 | J13: 165 | K13: 0
A14: 306 | B14: Allen , Karrington | C14: Past | F14: 45717 | G14: 45826 | H14: 13642.48 | I14: 0 | J14: 0 | K14: 13642.48
A15: 323 | B15: Boyd, Samantha | C15: Past | E15: Home: (813) 822-1101 | F15: 45717 | G15: 45899 | H15: 1085 | I15: 0 | J15: 465 | K15: 620
A16: 426 | B16: Pinet, Wilene | C16: Past | E16: Home: (305) 305-1241 | F16: 45717 | G16: 45757 | H16: 2420 | I16: 0 | J16: 0 | K16: 2420
H17: 54228.32 | I17: 0 | J17: 3317 | K17: 50911.32
A19: Total | H19: 54228.32 | I19: 0 | J19: 3317 | K19: 50911.32
H21: =H16+H14+H11+H10+H9+H8+H6+H4 -> 35427.84
H22: =H15+H12+H7+H5 -> 18635.48
H23: =H13 -> 165

Sheet Balance Sheet & IS
A1: Allaire on 41st top level
A2: Unaudited Consolidated Balance Sheet
A3: As of 9/30/2025
A6: ASSETS
A7: Cash and Cash Equivalents | B7: 1072818
A8: Accounts Receivable Intercompany | B8: 101712.79
A9: Prepaid Insurance | B9: 60248.17
A10: Prepaid Interest
A11: Prepaid Other
A12: Fixed Assets, Net | B12: 17423169
A13: Capitalized Loan Costs, Net | B13: 168204.2
A14: Deposits in Escrow | B14: 99209.46
A15: Property Tax in Escrow | B15: 215081.24
A16: Other Assets
A17: TOTAL ASSETS | B17: 19140443
A19: LIABILITIES AND EQUITY
A20: Liabilities
A21: Accounts Payable | B21: 8655.1596
A22: Property Taxes Payable | B22: 177461.29
A23: Management Fee Payable | B23: 36450
A24: Notes Payable | B24: 12180000
A25: Other Liabilities
A26: Total Liabilities | B26: 12402566
A27: Equity
A28: Members Equity | B28: 7290000
A29: Current Year Net Income | B29: -552123.24
A30: Accumulated Earnings & Profits
A31: Total Equity | B31: 6737876.8
A32: TOTAL LIABILITIES AND EQUITY | B32: 19140443
B34: -0.0099999979
A40: Allaire on 41st top level
A41: Unaudited Consolidated Income Statement
A42: January 1, 2025 through September 30, 2025
A45: REVENUES
A46: Rent Income | B46: 101104.75
A47: Distribution Income | B47: 485533.47
A48: Gross Profit | B48: 586638.22
A50: Acquisition Fees | B50: -344000
A51: Bank Fees | B51: -575
A52: Due Diligence | B52: -113505.01
...

Sheet Debt Service
A1: CITADEL ALLAIRE ON 41ST LLC
A2: Opening Balance | B2: 12180000
A3: Current Interest Rate | B3: 0.0586
A5: Monthly Interest | B5: 61461.63
A6: Tax Escrow | B6: 19552.84 | C6: =B6*12 -> 234634.08
A7: Insurance Escrow | B7: 10443.02
A8: Replacement Reserve Escrow | B8: 1708.33
A9: Total Payment | B9: =SUM(B5:B8) -> 93165.82

Sheet IS (Combined) (Q2)
A1: Income Statement
A2: As of: Jun 2025
A3: Accounting Basis: Accrual
A4: Level of Detail: Detail View
A5: Include Zero Balance GL Accounts: No
A7: Account Name | B7: Year to Month End
A8: Operating Income & Expense
A9: Income
A10: RENTS
A11: Rent Income | B11: =-'[5]TB Combined'!H25 -> 448013.01
A12: Section 8 Rent | B12: =-'[5]TB Combined'!H26 -> 3933
A13: Concessions | B13: =-'[5]TB Combined'!H27 -> -954.85
A14: Total RENTS | B14: =SUM(B11:B13) -> 450991.16
A15: FEES
A16: NSF/Returned Payment Fees | B16: =-'[5]TB Combined'!H28 -> 519.75
A17: Tenant Eviction/Legal Recovery | B17: =-'[5]TB Combined'!H29 -> 1435.46
A18: Pet Rent | B18: =-'[5]TB Combined'!H30 -> 113.4
A19: Application Fee Income | B19: =-'[5]TB Combined'!H31 -> 382.5
A20: Insurance Services | B20: =-'[5]TB Combined'!H32 -> 2661.86
A21: Insurance Admin Fees | B21: =-'[5]TB Combined'!H33 -> 30
A22: Security Deposit Insurance | B22: =-'[5]TB Combined'!H34 -> 2250
A23: Break Lease | B23: =-'[5]TB Combined'!H35 -> 3770.55
A24: Late Fee | B24: =-'[5]TB Combined'!H36 -> 4154.73
A25: Utility Reimbursement Fee | B25: =-'[5]TB Combined'!H37 -> 11881.92
A26: Garbage Fee | B26: =-'[5]TB Combined'!H38 -> -3823.65
A27: Total FEES | B27: =SUM(B16:B26) -> 23376.52
A28: Deposit Forfeit | B28: =-'[5]TB Combined'!H39 -> 7410
A29: Laundry Income | B29: =-'[5]TB Combined'!H40 -> 272.32
A30: Tenant Improvements | B30: =-'[5]TB Combined'!H41 -> 286.25
A31: Miscellaneous Income | B31: =-'[5]TB Combined'!H42 -> 1008.75
A32: Total Operating Income | B32: =SUM(B27:B31)+B14 -> 483345
A33: Expense
A34: CLEANING AND MAINTENANCE
A35: Supplies - Cleaning and Maitenance | B35: ='[5]TB Combined'!H43 -> 244.91
A36: Cleaning and Maintenance -Other | B36: ='[5]TB Combined'!H44 -> 4439.29
A37: Total CLEANING AND MAINTENANCE | B37: =SUM(B35:B36) -> 4684.2
A38: Permits & Licenses | B38: ='[5]TB Combined'!H45 -> 680.35
A39: CONTRACT SERVICES
A40: Elevator | B40: ='[5]TB Combined'!H46 -> 270
A41: Pool | B41: ='[5]TB Combined'!H47 -> 1475.76
...

Sheet Cash Flow
A1: Cash Flow
A2: Exported On: 07/27/2025 02:06 PM
A4: Cruise Property Management
A5: Properties: Active
A6: Date Range: 04/01/2025 to 06/30/2025 (Last Quarter)
A7: Accounting Basis: Accrual
A8: Additional Cash GL Accounts: 1102: Security Account, 1137: Due From/To, and 1150: Exchange/Transfer
A9: Level of Detail: Detail View
A10: Include Zero Balance GL Accounts: No
A12: Account Name | B12: Selected Period | C12: % of Selected Period | D12: Fiscal Year To Date | E12: % of Fiscal Year To Date
A13: Operating Income & Expense
A14: Income
A15: RENTS
A16: Rent Income | B16: 346908.26 | C16: 90.76 | D16: 346908.26 | E16: 90.76
A17: Section 8 Rent | B17: 3933 | C17: 1.03 | D17: 3933 | E17: 1.03
A18: Concessions | B18: -954.85 | C18: -0.25 | D18: -954.85 | E18: -0.25
A19: Total RENTS | B19: 349886.41 | C19: 91.54 | D19: 349886.41 | E19: 91.54
A20: FEES
A21: NSF/Returned Payment Fees | B21: 519.75 | C21: 0.14 | D21: 519.75 | E21: 0.14
A22: Tenant Eviction/Legal Recovery | B22: 1435.46 | C22: 0.38 | D22: 1435.46 | E22: 0.38
A23: Pet Rent | B23: 113.4 | C23: 0.03 | D23: 113.4 | E23: 0.03
A24: Application Fee Income | B24: 382.5 | C24: 0.1 | D24: 382.5 | E24: 0.1
A25: Insurance Services | B25: 2661.86 | C25: 0.7 | D25: 2661.86 | E25: 0.7
A26: Insurance Admin Fees | B26: 30 | C26: 0.01 | D26: 30 | E26: 0.01
A27: Security Deposit Insurance | B27: 2250 | C27: 0.59 | D27: 2250 | E27: 0.59
A28: Break Lease | B28: 3770.55 | C28: 0.99 | D28: 3770.55 | E28: 0.99
A29: Late Fee | B29: 4154.73 | C29: 1.09 | D29: 4154.73 | E29: 1.09
A30: Utility Reimbursement Fee | B30: 11881.92 | C30: 3.11 | D30: 11881.92 | E30: 3.11
A31: Garbage Fee | B31: -3823.65 | C31: -1 | D31: -3823.65 | E31: -1
A32: Total FEES | B32: 23376.52 | C32: 6.12 | D32: 23376.52 | E32: 6.12
... A37: Total Operating Income | B37: 382240.25 | C37: 100 | D37: 382240.25 | E37: 100
A38: Expense
A39: CLEANING AND MAINTENANCE
A40: Supplies - Cleaning and Maitenance | B40: 244.91 | C40: 0.06 | D40: 244.91 | E40: 0.06
A41: Cleaning and Maintenance -Other | B41: 4439.29 | C41: 1.16 | D41: 4439.29 | E41: 1.16
A42: Total CLEANING AND MAINTENANCE | B42: 4684.2 | C42: 1.23 | D42: 4684.2 | E42: 1.23
A43: Permits & Licenses | B43: 680.35 | C43: 0.18 | D43: 680.35 | E43: 0.18
A44: CONTRACT SERVICES
A45: Elevator | B45: 270 | C45: 0.07 | D45: 270 | E45: 0.07
A46: Pool | B46: 1475.76 | C46: 0.39 | D46: 1475.76 | E46: 0.39
...
